{
  "cve": {
    "data_type": "CVE",
    "data_format": "MITRE",
    "data_version": "4.0",
    "CVE_data_meta": {
      "ID": "CVE-2019-19588",
      "ASSIGNER": "cve@mitre.org"
    },
    "affects": {
      "vendor": {
        "vendor_data": [
          {
            "vendor_name": "validators_project",
            "product": {
              "product_data": [
                {
                  "product_name": "validators",
                  "version": {
                    "version_data": [
                      {
                        "version_value": "0.12.2",
                        "version_affected": "="
                      },
                      {
                        "version_value": "0.12.3",
                        "version_affected": "="
                      },
                      {
                        "version_value": "0.12.4",
                        "version_affected": "="
                      },
                      {
                        "version_value": "0.12.5",
                        "version_affected": "="
                      }
                    ]
                  }
                }
              ]
            }
          }
        ]
      }
    },
    "problemtype": {
      "problemtype_data": [
        {
          "description": [
            {
              "lang": "en",
              "value": "CWE-400"
            }
          ]
        }
      ]
    },
    "references": {
      "reference_data": [
        {
          "url": "https://github.com/kvesteri/validators/issues/86",
          "name": "https://github.com/kvesteri/validators/issues/86",
          "refsource": "MISC",
          "tags": [
            "Exploit",
            "Third Party Advisory"
          ]
        }
      ]
    },
    "description": {
      "description_data": [
        {
          "lang": "en",
          "value": "The validators package 0.12.2 through 0.12.5 for Python enters an infinite loop when validators.domain is called with a crafted domain string. This is fixed in 0.12.6."
        }
      ]
    }
  },
  "configurations": {
    "CVE_data_version": "4.0",
    "nodes": [
      {
        "operator": "OR",
        "cpe_match": [
          {
            "vulnerable": true,
            "cpe23Uri": "cpe:2.3:a:validators_project:validators:*:*:*:*:*:python:*:*",
            "versionStartIncluding": "0.12.2",
            "versionEndIncluding": "0.12.5"
          }
        ]
      }
    ]
  },
  "impact": {
    "baseMetricV2": {
      "cvssV2": {
        "version": "2.0",
        "vectorString": "AV:N/AC:L/Au:N/C:N/I:N/A:C",
        "accessVector": "NETWORK",
        "accessComplexity": "LOW",
        "authentication": "NONE",
        "confidentialityImpact": "NONE",
        "integrityImpact": "NONE",
        "availabilityImpact": "COMPLETE",
        "baseScore": 7.8
      },
      "severity": "HIGH",
      "exploitabilityScore": 10.0,
      "impactScore": 6.9,
      "acInsufInfo": false,
      "obtainAllPrivilege": false,
      "obtainUserPrivilege": false,
      "obtainOtherPrivilege": false,
      "userInteractionRequired": false
    }
  },
  "publishedDate": "2019-12-05T01:15Z",
  "lastModifiedDate": "2019-12-09T17:20Z"
}