{
  "cve": {
    "data_type": "CVE",
    "data_format": "MITRE",
    "data_version": "4.0",
    "CVE_data_meta": {
      "ID": "CVE-2019-18874",
      "ASSIGNER": "cve@mitre.org"
    },
    "affects": {
      "vendor": {
        "vendor_data": [
          {
            "vendor_name": "psutil_project",
            "product": {
              "product_data": [
                {
                  "product_name": "psutil",
                  "version": {
                    "version_data": [
                      {
                        "version_value": "5.6.5",
                        "version_affected": "<="
                      }
                    ]
                  }
                }
              ]
            }
          }
        ]
      }
    },
    "problemtype": {
      "problemtype_data": [
        {
          "description": [
            {
              "lang": "en",
              "value": "CWE-415"
            }
          ]
        }
      ]
    },
    "references": {
      "reference_data": [
        {
          "url": "https://github.com/giampaolo/psutil/pull/1616",
          "name": "https://github.com/giampaolo/psutil/pull/1616",
          "refsource": "MISC",
          "tags": [
            "Third Party Advisory"
          ]
        },
        {
          "url": "https://lists.debian.org/debian-lts-announce/2019/11/msg00018.html",
          "name": "[debian-lts-announce] 20191118 [SECURITY] [DLA 1998-1] python-psutil security update",
          "refsource": "MLIST",
          "tags": [

          ]
        },
        {
          "url": "https://lists.fedoraproject.org/archives/list/package-announce@lists.fedoraproject.org/message/2P7QI7MOTZTFXQYU23CP3RAWXCERMOAS/",
          "name": "FEDORA-2020-a06ebafad8",
          "refsource": "FEDORA",
          "tags": [

          ]
        },
        {
          "url": "https://usn.ubuntu.com/4204-1/",
          "name": "USN-4204-1",
          "refsource": "UBUNTU",
          "tags": [

          ]
        }
      ]
    },
    "description": {
      "description_data": [
        {
          "lang": "en",
          "value": "psutil (aka python-psutil) through 5.6.5 can have a double free. This occurs because of refcount mishandling within a while or for loop that converts system data into a Python object."
        }
      ]
    }
  },
  "configurations": {
    "CVE_data_version": "4.0",
    "nodes": [
      {
        "operator": "OR",
        "cpe_match": [
          {
            "vulnerable": true,
            "cpe23Uri": "cpe:2.3:a:psutil_project:psutil:*:*:*:*:*:*:*:*",
            "versionEndIncluding": "5.6.5"
          }
        ]
      }
    ]
  },
  "impact": {
    "baseMetricV2": {
      "cvssV2": {
        "version": "2.0",
        "vectorString": "AV:N/AC:L/Au:N/C:N/I:N/A:P",
        "accessVector": "NETWORK",
        "accessComplexity": "LOW",
        "authentication": "NONE",
        "confidentialityImpact": "NONE",
        "integrityImpact": "NONE",
        "availabilityImpact": "PARTIAL",
        "baseScore": 5.0
      },
      "severity": "MEDIUM",
      "exploitabilityScore": 10.0,
      "impactScore": 2.9,
      "acInsufInfo": false,
      "obtainAllPrivilege": false,
      "obtainUserPrivilege": false,
      "obtainOtherPrivilege": false,
      "userInteractionRequired": false
    }
  },
  "publishedDate": "2019-11-12T02:15Z",
  "lastModifiedDate": "2019-11-18T21:15Z"
}